<?xml version="1.0"?>
<robot xmlns:xacro="http://ros.org/wiki/xacro" name="jbot" >

  <!-- body -->
  <xacro:include filename="$(find jbot_description)/urdf/jbot_description.urdf" />

  <!-- slider -->
  <xacro:include filename="$(find jbot_description)/urdf/slider.urdf" />

  <!-- right arm -->
  <xacro:include filename="$(find jbot_description)/urdf/xbot_urdf.urdf" />
  <!-- left arm -->
  <xacro:include filename="$(find jbot_description)/urdf/xbot_urdf_left.urdf" />

  <!-- arm -->
  <!--xacro:jbot prefix="" joint_limited="false"/-->

  <link name="base_footprint" />
  <joint name="base_footprint_joint" type="fixed">
    <parent link="base_footprint" />
    <child link = "base_link" />
    <origin xyz="0.0 0.0 0.0" rpy="0.0 0.0 0.0" />
  </joint>

  <joint name="joint_slider" type="prismatic">
    <!--origin
      xyz="0.085592 0 0.242"
      rpy="3.9766E-16 5.1321E-17 3.5611E-33" /-->
    <origin xyz="0.085592 0 0.50"
      rpy="3.9766E-16 5.1321E-17 3.5611E-33" />
    <parent link="base_link" />
    <child link="slider_link" />
    <axis xyz="0 0 1" />
    <limit
      lower="0"
      upper="0.5"
      effort="200"
      velocity="0.1" />
  </joint>

  <joint name="joint_right_arm" type="fixed">
    <origin xyz="-0.024519 0.089 0.03"
      rpy="-1.5708 -1.502E-16 -1.3151E-12" />
    <parent link="slider_link" />
    <child link="arm_base_link" />
    <axis xyz="0 0 0" />
  </joint>

  <joint name="joint_left_arm" type="fixed">
   <origin
      xyz="-0.024519 -0.089 0.03"
      rpy="-1.5708 1.502E-16 3.1416" />
    <parent link="slider_link" />
    <child link="arm_base_link_left" />
    <axis xyz="0 0 0" />
  </joint>
  
  <link name="laser" />
  <joint name="joint_laser" type="fixed">
    <origin xyz="0.215 0 0.152" rpy="0 0 3.14" />
    <parent link="base_link" />
    <child link="laser" />
    <axis xyz="0 0 0" />
  </joint>

  <link name="link_camera" />
  <joint  name="joint_camera"  type="fixed">
    <origin  xyz="0.0856 0 0.751" rpy="0 0 0" />
    <parent link="base_link" />
    <child link="link_camera" />
    <axis xyz="0 0 0" />
  </joint>

  <transmission name="tran1">  
  <type>transmission_interface/SimpleTransmission</type>  
  <joint name="joint_wheel_1">  
    <hardwareInterface>EffortJointInterface</hardwareInterface>  
  </joint>  
  <actuator name="motor1">  
    <hardwareInterface>EffortJointInterface</hardwareInterface>  
    <mechanicalReduction>1</mechanicalReduction>  
  </actuator>  
  </transmission>

  <transmission name="tran2">  
  <type>transmission_interface/SimpleTransmission</type>  
  <joint name="joint_wheel_2">  
    <hardwareInterface>EffortJointInterface</hardwareInterface>  
  </joint>  
  <actuator name="motor2">  
    <hardwareInterface>EffortJointInterface</hardwareInterface>  
    <mechanicalReduction>1</mechanicalReduction>  
  </actuator>  
  </transmission>  

  <transmission name="tran3">  
  <type>transmission_interface/SimpleTransmission</type>  
  <joint name="joint_wheel_3">  
    <hardwareInterface>EffortJointInterface</hardwareInterface>  
  </joint>  
  <actuator name="motor3">  
    <hardwareInterface>EffortJointInterface</hardwareInterface>  
    <mechanicalReduction>1</mechanicalReduction>  
  </actuator>  
  </transmission>  

  <transmission name="tran4">  
  <type>transmission_interface/SimpleTransmission</type>  
  <joint name="joint_wheel_4">  
    <hardwareInterface>EffortJointInterface</hardwareInterface>  
  </joint>  
  <actuator name="motor4">  
    <hardwareInterface>EffortJointInterface</hardwareInterface>  
    <mechanicalReduction>1</mechanicalReduction>  
  </actuator>  
  </transmission>  

</robot>
